Workbook

Sheet Read me
A1: Nani jo Ghar — Content master
A2: One tab per scene. The scene tabs are where words get checked; the master list only reads from them.
A4: What's new in this version
A5: Freelang's Kutchi-English dictionary (496 entries, one compiler's record — Burhan Khamisa) has been cross-
A6: referenced against every word already in the file. Matches are noted as extra confirmation. Genuine conflicts —
A7: where Freelang gives a different word to the handout for the same English meaning — are flagged pink and both
A8: forms are shown side by side. Neither source wins automatically; only the family can settle a real conflict.
A9: Produce nouns (fruit, vegetables) now carry an extra pair of columns for the plural form, because Nani's opening
A10: line names a quantity out loud ('I need two lemons'), so the app needs to know what changes when it's not one.
A12: How this file works
A13: Each scene — Bazaar, Doorstep, Street, Charades, Clinic, Hide and Seek, Pack the Bag, Bonus — has its own tab.
A14: Go through one scene at a time. Fill kutchi_confirmed (and kutchi_plural_confirmed on the Bazaar tab, where
... A66: most of the spice list.

Sheet Scene — Bazaar
A1: id | B1: group | C1: english | D1: kutchi_draft | E1: draft_source | F1: kutchi_confirmed | G1: audio_status | H1: image_ref | I1: notes | J1: kutchi_plural_draft | K1: kutchi_plural_confirmed | L1: plural_notes
A2: fru-01 | B2: fruit | C2: banana | D2: kelo | E2: handout | G2: tts | H2: fruit-sheet r1c1 | I2: FaL.pdf; Rhyme Unit 6 ('Hikdo keLo'). Freelang independently gives 'kero' for banana — likely the same word, r/l spelling difference; only appeared at quantity one in the rhyme, so no plural evidence yet
A3: fru-02 | B3: fruit | C3: lemon | D3: limu | E3: handout | G3: tts | H3: fruit-sheet r1c2 | I3: FaL.pdf; Rhyme Unit 6 ('Bo limu'); Game Design doc's worked example. Freelang gives 'limboo' — likely the same word, spelling variant | J3: limu | L3: Rhyme Unit 6: 'Bo limu' (two lemons) — word does not change
A4: fru-03 | B4: fruit | C4: papaya | D4: papaiyo | E4: handout | G4: tts | H4: fruit-sheet r1c3 | I4: FaL.pdf; Rhyme Unit 6 ('Papaiya') | J4: papaiya | L4: Rhyme Unit 6: 'Tre Papaiya' (three papayas) — o becomes a
A5: fru-04 | B5: fruit | C5: orange | D5: santra | E5: handout | G5: tts | H5: fruit-sheet r1c4 | I5: FaL.pdf; homework.docx; Game Design doc's worked example | J5: santra | L5: Rhyme Unit 6: 'Panj Santra' (five oranges) — word does not change (already ends in -a)
A6: fru-05 | B6: fruit | C6: mango | D6: aamo | E6: handout | G6: tts | H6: fruit-sheet r2c1 | I6: CONFLICT — FaL.pdf gives 'aamo/aama'; Rhyme Unit 6 ('Chh Aama'). Freelang independently gives an entirely different word, 'keri', for mango — possibly 'keri' means specifically an unripe/raw mango rather than mango in general. Two real candidates, needs the family to choose or distinguish | J6: aama | L6: Rhyme Unit 6: 'Chh Aama' (six mangoes) — o becomes a
A7: fru-06 | B7: fruit | C7: pear | D7: naaspati | E7: handout | G7: tts | H7: fruit-sheet r2c2 | I7: FaL.pdf; Rhyme Unit 6; homework.docx ('Hukro naaspati') | J7: naaspati | L7: Rhyme Unit 6: 'Sat naaspati' (seven pears) — word does not change
A8: fru-07 | B8: fruit | C8: kiwi | D8: kivi | E8: handout | G8: tts | H8: fruit-sheet r2c3 | I8: FaL.pdf; Rhyme Unit 6 ('ath kivi'). Loanword | J8: kivi | L8: Rhyme Unit 6: 'Ath kivi' (eight kiwis) — word does not change (loanword)
A9: fru-08 | B9: fruit | C9: apple | D9: safarjan | E9: handout | G9: tts | H9: fruit-sheet r2c4 | I9: CONFLICT — FaL.pdf; homework.docx ('safarjaan'); Unit 8 ('safarajan'). Freelang independently gives an entirely different word, 'sayb' (essentially the Hindi/Urdu 'seb'). Two real candidates from two sources, needs the family to choose
A10: fru-09 | B10: fruit | C10: coconut | D10: naariyel | E10: handout | G10: tts | H10: fruit-sheet r3c1 | I10: FaL.pdf ('naariyeL'). Not in Freelang
A11: fru-10 | B11: fruit | C11: fig | D11: anjir | E11: handout | G11: tts | H11: fruit-sheet r3c2 | I11: FaL.pdf ('anjir'). Not in Freelang
A12: fru-11 | B12: fruit | C12: grapes | D12: drakhu | E12: handout | G12: tts | H12: fruit-sheet r3c3 | I12: FaL.pdf ('Drakhu'). Not in Freelang
A13: fru-12 | B13: fruit | C13: pineapple | D13: ananas | E13: handout | G13: tts | H13: fruit-sheet r3c4 | I13: FaL.pdf ('anānas'). Not in Freelang
A14: fru-13 | B14: fruit | C14: peach | D14: peach | E14: handout | G14: tts | H14: fruit-sheet r4c1 | I14: FaL.pdf lists it in English ('peach'/'pich') — no separate Kutchi word taught. Not in Freelang
A15: fru-14 | B15: fruit | C15: cherry | D15: cheree | E15: handout | G15: tts | H15: fruit-sheet r4c2 | I15: FaL.pdf. Loanword. Not in Freelang
A16: fru-15 | B16: fruit | C16: lychee | D16: litchi | E16: handout | G16: tts | H16: fruit-sheet r4c3 | I16: FaL.pdf. Loanword. Not in Freelang
A17: fru-16 | B17: fruit | C17: pomegranate | D17: daadam | E17: sindhi-cognate | G17: tts | H17: fruit-sheet r4c4 | I17: Not in the handouts, not in Freelang, not in the blog dictionary. Still an unsourced guess, needs the family
A18: veg-01 | B18: vegetable | C18: potato | D18: bataato | E18: freelang | G18: tts | H18: veg-sheet r1c1 | I18: Freelang. Close to an earlier unsourced guess ('batato') — same word, spelling only
A19: veg-02 | B19: vegetable | C19: onion | D19: dungri | E19: sindhi-cognate | G19: tts | H19: veg-sheet r1c2 | I19: Not in the handouts or Freelang
A20: veg-03 | B20: vegetable | C20: tomato | D20: tameto | E20: sindhi-cognate | G20: tts | H20: veg-sheet r1c3 | I20: Not in the handouts or Freelang
... A49: spi-16 | B49: spice | C49: salt | D49: loon | E49: sindhi-cognate | G49: tts | H49: spice-sheet r4c4 | I49: Not in the handouts, already a Sindhi-form guess. Not in Freelang
A50: num-01 | B50: number | C50: one | D50: hikdo | E50: handout | G50: tts | I50: Unit 1 - Rhyme.pdf. Also 'hukro' (homework.docx) and gendered 'hakdo/hakdi' (Unit1Translation.pdf). kutchidictionary.home.blog gives 'hakdo'. Freelang gives 'hakro' — close to 'hakdo'. Several spoken forms recorded; the gendered hakdo(m)/hakdi(f) pair is likely the real grammar and the others are dialect or casual variants — needs the family to confirm
A51: num-02 | B51: number | C51: two | D51: bo | E51: handout | G51: tts | I51: Confirmed by kutchidictionary.home.blog and Freelang
A52: num-03 | B52: number | C52: three | D52: trae | E52: handout | G52: tts | I52: Also 'tre' — spelling only. Confirmed by kutchidictionary.home.blog and Freelang ('ttre')
A53: num-04 | B53: number | C53: four | D53: char | E53: handout | G53: tts | I53: Confirmed by kutchidictionary.home.blog and Freelang ('chaar')
A54: num-05 | B54: number | C54: five | D54: panj | E54: handout | G54: tts | I54: Confirmed by kutchidictionary.home.blog and Freelang
A55: num-06 | B55: number | C55: six | D55: chh | E55: handout | G55: tts | I55: Confirmed by kutchidictionary.home.blog and Freelang ('ccho')
A56: num-07 | B56: number | C56: seven | D56: sat | E56: handout | G56: tts | I56: Confirmed by kutchidictionary.home.blog and Freelang ('satt')
A57: num-08 | B57: number | C57: eight | D57: ath | E57: handout | G57: tts | I57: Confirmed by kutchidictionary.home.blog and Freelang ('atth')
A58: num-09 | B58: number | C58: nine | D58: no | E58: handout | G58: tts | I58: Confirmed by kutchidictionary.home.blog. Freelang gives 'nu' — spelling variant only
A59: num-10 | B59: number | C59: ten | D59: do | E59: handout | G59: tts | I59: Confirmed by kutchidictionary.home.blog. Freelang gives 'dow' — spelling variant only

Sheet Sentences (Bazaar)
A1: id | B1: function | C1: english | D1: kutchi_draft | E1: draft_source | F1: kutchi_confirmed | G1: audio_status | H1: slot | I1: notes
A2: snt-01 | B2: greeting | C2: Peace be upon you | D2: Salamun alaykum | E2: handout | G2: tts | H2: Nani, shopkeeper | I2: Unit 2, Unit 9 — exact match, high confidence
A3: snt-02 | B3: greeting reply | C3: And peace be upon you too | D3: Wa alaikum salaam | E3: handout | G3: tts | H3: Shopkeeper reply | I3: Unit 9 ('Wa alaikum salām chhokra!')
A4: snt-03 | B4: call | C4: Hey! | D4: Hedo! | E4: doc | G4: tts | H4: Nani | I4: From the Game Design doc's worked example, not independently seen in the handouts
A5: snt-04 | B5: template | C5: I need {word} | D5: Muke {word} khape | E5: handout | G5: tts | H5: {word} | I5: Unit 9 ('muke Dai nathi khape' — I don't want curd) confirms 'khape' as the want/need verb. Freelang confirms 'khhape' = want
A6: snt-05 | B6: template | C6: And {word} | D6: Ne {word} | E6: doc | G6: tts | H6: {word} | I6: 'Ne' as 'and' appears throughout the handouts, e.g. Unit 6 rhyme
A7: snt-06 | B7: instruction | C7: Go to the market | D7: Bajaar mai vaan | E7: doc | G7: tts | I7: Handout has the related 'Aau bajaar mai vanato' (I am going to market) in Rhyme Unit 6, but not this imperative form
A8: snt-07 | B8: warm failure | C8: Oh dear! | D8: Arre re! | E8: doc | G8: tts | I8: Not seen in the handouts
A9: snt-08 | B9: shopkeeper | C9: What would you like? | G9: tts | I9: Needs the family
A10: snt-09 | B10: shopkeeper | C10: How many? | G10: tts | I10: Needs the family. Sets up the numbers
A11: snt-10 | B11: shopkeeper | C11: Here you are / take it | D11: Ghan | E11: handout | G11: tts | I11: Unit 9 ('Rayhān: ghan!' — take it, said handing over papad). Needs the family to confirm this fits a shop handover
A12: snt-11 | B12: shopkeeper | C12: Thank you | D12: Aabhar aanjo | E12: handout | G12: tts | I12: Unit 5 ('Aabhar aanjo! Achija.' — thank you, bye)
A13: snt-12 | B13: template | C13: Give me the {word} | D13: Muke hikdo {word} dine | E13: handout | G13: tts | H13: {word} | I13: Unit 9 ('muke hikdo papaD dine!'), gives the real word order for this frame
A14: snt-13 | B14: praise | C14: Well done! | G14: tts | I14: Needs the family. 'Bahu j saras aay' (very nice) was used by Meena Aunty in the chat but as a comment, not confirmed as in-game praise
A15: snt-14 | B15: farewell | C15: Bye | D15: Achija | E15: handout | G15: tts | I15: Unit 5. Bonus, not yet placed in a scene

Sheet Carrier sentences
A1: One whole-sentence recording per item, because splicing word recordings together sounds robotic. The singular column builds itself from the Scene — Bazaar tab's kutchi_confirmed/kutchi_draft. The plural example does the same from kutchi_plural_confirmed/kutchi_plural_draft, where that exists — most rows are blank there until the family confirms a plural. Do not type in either grey column.
A2: id | B2: word_id | C2: english | D2: kutchi (auto, singular) | E2: kutchi (auto, 2x example) | F2: audio_status | G2: notes
A3: car-01 | B3: fru-01 | C3: I need banana | D3: =IF('Scene — Bazaar'!F2<>"","Muke "&'Scene — Bazaar'!F2&" khape",IF('Scene — Bazaar'!D2<>"","Muke "&'Scene — Bazaar'!D2&" khape","")) -> Muke kelo khape | E3: =IF('Scene — Bazaar'!K2<>"","Muke bo "&'Scene — Bazaar'!K2&" khape",IF('Scene — Bazaar'!J2<>"","Muke bo "&'Scene — Bazaar'!J2&" khape","")) | F3: tts
A4: car-02 | B4: fru-02 | C4: I need lemon | D4: =IF('Scene — Bazaar'!F3<>"","Muke "&'Scene — Bazaar'!F3&" khape",IF('Scene — Bazaar'!D3<>"","Muke "&'Scene — Bazaar'!D3&" khape","")) -> Muke limu khape | E4: =IF('Scene — Bazaar'!K3<>"","Muke bo "&'Scene — Bazaar'!K3&" khape",IF('Scene — Bazaar'!J3<>"","Muke bo "&'Scene — Bazaar'!J3&" khape","")) -> Muke bo limu khape | F4: tts
A5: car-03 | B5: fru-03 | C5: I need papaya | D5: =IF('Scene — Bazaar'!F4<>"","Muke "&'Scene — Bazaar'!F4&" khape",IF('Scene — Bazaar'!D4<>"","Muke "&'Scene — Bazaar'!D4&" khape","")) -> Muke papaiyo khape | E5: =IF('Scene — Bazaar'!K4<>"","Muke bo "&'Scene — Bazaar'!K4&" khape",IF('Scene — Bazaar'!J4<>"","Muke bo "&'Scene — Bazaar'!J4&" khape","")) -> Muke bo papaiya khape | F5: tts
A6: car-04 | B6: fru-04 | C6: I need orange | D6: =IF('Scene — Bazaar'!F5<>"","Muke "&'Scene — Bazaar'!F5&" khape",IF('Scene — Bazaar'!D5<>"","Muke "&'Scene — Bazaar'!D5&" khape","")) -> Muke santra khape | E6: =IF('Scene — Bazaar'!K5<>"","Muke bo "&'Scene — Bazaar'!K5&" khape",IF('Scene — Bazaar'!J5<>"","Muke bo "&'Scene — Bazaar'!J5&" khape","")) -> Muke bo santra khape | F6: tts
A7: car-05 | B7: fru-05 | C7: I need mango | D7: =IF('Scene — Bazaar'!F6<>"","Muke "&'Scene — Bazaar'!F6&" khape",IF('Scene — Bazaar'!D6<>"","Muke "&'Scene — Bazaar'!D6&" khape","")) -> Muke aamo khape | E7: =IF('Scene — Bazaar'!K6<>"","Muke bo "&'Scene — Bazaar'!K6&" khape",IF('Scene — Bazaar'!J6<>"","Muke bo "&'Scene — Bazaar'!J6&" khape","")) -> Muke bo aama khape | F7: tts
A8: car-06 | B8: fru-06 | C8: I need pear | D8: =IF('Scene — Bazaar'!F7<>"","Muke "&'Scene — Bazaar'!F7&" khape",IF('Scene — Bazaar'!D7<>"","Muke "&'Scene — Bazaar'!D7&" khape","")) -> Muke naaspati khape | E8: =IF('Scene — Bazaar'!K7<>"","Muke bo "&'Scene — Bazaar'!K7&" khape",IF('Scene — Bazaar'!J7<>"","Muke bo "&'Scene — Bazaar'!J7&" khape","")) -> Muke bo naaspati khape | F8: tts
A9: car-07 | B9: fru-07 | C9: I need kiwi | D9: =IF('Scene — Bazaar'!F8<>"","Muke "&'Scene — Bazaar'!F8&" khape",IF('Scene — Bazaar'!D8<>"","Muke "&'Scene — Bazaar'!D8&" khape","")) -> Muke kivi khape | E9: =IF('Scene — Bazaar'!K8<>"","Muke bo "&'Scene — Bazaar'!K8&" khape",IF('Scene — Bazaar'!J8<>"","Muke bo "&'Scene — Bazaar'!J8&" khape","")) -> Muke bo kivi khape | F9: tts
A10: car-08 | B10: fru-08 | C10: I need apple | D10: =IF('Scene — Bazaar'!F9<>"","Muke "&'Scene — Bazaar'!F9&" khape",IF('Scene — Bazaar'!D9<>"","Muke "&'Scene — Bazaar'!D9&" khape","")) -> Muke safarjan khape | E10: =IF('Scene — Bazaar'!K9<>"","Muke bo "&'Scene — Bazaar'!K9&" khape",IF('Scene — Bazaar'!J9<>"","Muke bo "&'Scene — Bazaar'!J9&" khape","")) | F10: tts
A11: car-09 | B11: fru-09 | C11: I need coconut | D11: =IF('Scene — Bazaar'!F10<>"","Muke "&'Scene — Bazaar'!F10&" khape",IF('Scene — Bazaar'!D10<>"","Muke "&'Scene — Bazaar'!D10&" khape","")) -> Muke naariyel khape | E11: =IF('Scene — Bazaar'!K10<>"","Muke bo "&'Scene — Bazaar'!K10&" khape",IF('Scene — Bazaar'!J10<>"","Muke bo "&'Scene — Bazaar'!J10&" khape","")) | F11: tts
A12: car-10 | B12: fru-10 | C12: I need fig | D12: =IF('Scene — Bazaar'!F11<>"","Muke "&'Scene — Bazaar'!F11&" khape",IF('Scene — Bazaar'!D11<>"","Muke "&'Scene — Bazaar'!D11&" khape","")) -> Muke anjir khape | E12: =IF('Scene — Bazaar'!K11<>"","Muke bo "&'Scene — Bazaar'!K11&" khape",IF('Scene — Bazaar'!J11<>"","Muke bo "&'Scene — Bazaar'!J11&" khape","")) | F12: tts
A13: car-11 | B13: fru-11 | C13: I need grapes | D13: =IF('Scene — Bazaar'!F12<>"","Muke "&'Scene — Bazaar'!F12&" khape",IF('Scene — Bazaar'!D12<>"","Muke "&'Scene — Bazaar'!D12&" khape","")) -> Muke drakhu khape | E13: =IF('Scene — Bazaar'!K12<>"","Muke bo "&'Scene — Bazaar'!K12&" khape",IF('Scene — Bazaar'!J12<>"","Muke bo "&'Scene — Bazaar'!J12&" khape","")) | F13: tts
A14: car-12 | B14: fru-12 | C14: I need pineapple | D14: =IF('Scene — Bazaar'!F13<>"","Muke "&'Scene — Bazaar'!F13&" khape",IF('Scene — Bazaar'!D13<>"","Muke "&'Scene — Bazaar'!D13&" khape","")) -> Muke ananas khape | E14: =IF('Scene — Bazaar'!K13<>"","Muke bo "&'Scene — Bazaar'!K13&" khape",IF('Scene — Bazaar'!J13<>"","Muke bo "&'Scene — Bazaar'!J13&" khape","")) | F14: tts
... A50: car-48 | B50: spi-16 | C50: I need salt | D50: =IF('Scene — Bazaar'!F49<>"","Muke "&'Scene — Bazaar'!F49&" khape",IF('Scene — Bazaar'!D49<>"","Muke "&'Scene — Bazaar'!D49&" khape","")) -> Muke loon khape | E50: =IF('Scene — Bazaar'!K49<>"","Muke bo "&'Scene — Bazaar'!K49&" khape",IF('Scene — Bazaar'!J49<>"","Muke bo "&'Scene — Bazaar'!J49&" khape","")) | F50: tts

Sheet Scene — Doorstep
A1: id | B1: group | C1: english | D1: kutchi_draft | E1: draft_source | F1: kutchi_confirmed | G1: audio_status | H1: image_ref | I1: notes
A2: door-01 | B2: greeting | C2: how are you | D2: Ki aiye? / Ki ayo? | E2: handout | G2: tts | I2: Unit 2 - Main text.pdf
A3: door-02 | B3: greeting | C3: I am fine | D3: Aau sari/saro aiya | E3: handout | G3: tts | I3: Unit 2 - Main text.pdf
A4: door-03 | B4: greeting | C4: I am fine (alt.) | D4: Aau majame | E4: handout | G4: tts | I4: Unit 2 - Main text.pdf
A5: door-04 | B5: greeting | C5: I am fine (alt.) | D5: Aau bharobhar aiya | E5: handout | G5: tts | I5: Unit 2 - Main text.pdf
A6: door-05 | B6: greeting | C6: I am fine (alt.) | D6: Aau thik aiya | E6: handout | G6: tts | I6: Unit 2 - Main text.pdf
A7: door-06 | B7: greeting | C7: I am ill | D7: Aau mando/mandi aiya | E7: handout | G7: tts | I7: Unit 2 - Main text.pdf
A8: door-07 | B8: greeting | C8: I am tired | D8: Aau thake rai/ryo aiya | E8: handout | G8: tts | I8: Unit 2 - Main text.pdf
A9: door-08 | B9: greeting | C9: I am not well | D9: Muke thik naay | E9: handout | G9: tts | I9: Unit 2 - Main text.pdf
A10: door-09 | B10: greeting | C10: peace be upon you | D10: Salamun alaykum | E10: handout | G10: tts | I10: Unit 2; Unit 9. Also ships in the Bazaar Sentences tab
A11: door-10 | B11: greeting | C11: and peace be upon you | D11: Wa alaikum salaam | E11: handout | G11: tts | I11: Unit 9. Also ships in the Bazaar Sentences tab

Sheet Scene — Street
A1: FLAGGED: 'baai' is used by the handout to mean mother, but Freelang gives 'baai' for SISTER and 'maa' for mother. The same word claimed for two different relatives by two different sources — settle this before recording any family terms, since it affects both str-02 and str-08 below.
A2: id | B2: group | C2: english | D2: kutchi_draft | E2: draft_source | F2: kutchi_confirmed | G2: audio_status | H2: image_ref | I2: notes
A3: str-01 | B3: family | C3: father | D3: adhha / bapuji | E3: handout | G3: tts | I3: Unit 3. Freelang gives a completely different word, 'pe' — possibly a more casual/colloquial form. Needs the family
A4: str-02 | B4: family | C4: mother | D4: baai | E4: handout | G4: tts | I4: CONFLICT — Unit 3. Freelang gives 'maa' for mother, and separately gives 'baai' for sister (see str-08). See the flag at the top of this tab
A5: str-03 | B5: family | C5: grandfather (paternal) | D5: dadobapa | E5: handout | G5: tts | I5: Unit 3; Rhyme Unit 3. Freelang gives the shorter 'daado' — likely the same root, a compound vs. a short form
A6: str-04 | B6: family | C6: grandmother (paternal) | D6: dadi | E6: handout | G6: tts | I6: Unit 3; Rhyme Unit 3. Confirmed by Freelang exactly
A7: str-05 | B7: family | C7: grandmother (maternal) | D7: naani | E7: handout | G7: tts | I7: Rhyme Unit 3 — the Nani of the game's title. Confirmed by Freelang exactly
A8: str-06 | B8: family | C8: grandfather (maternal) | D8: naanobapa | E8: handout | G8: tts | I8: Rhyme Unit 3. Freelang gives the shorter 'naana' — likely the same root, a compound vs. a short form
A9: str-07 | B9: family | C9: brother | D9: bha | E9: handout | G9: tts | I9: Unit 3; Rhyme Unit 3. Confirmed by Freelang ('bhaa')
A10: str-08 | B10: family | C10: sister | D10: bheN | E10: handout | G10: tts | I10: CONFLICT — Unit 3; Rhyme Unit 3. Freelang instead gives 'baai' for sister, which the handout uses for mother (see str-02 and the flag at the top of this tab)
A11: str-09 | B11: family | C11: aunt (father's sister) | D11: fui | E11: handout | G11: tts | I11: Rhyme Unit 3; Unit 9. Confirmed by Freelang exactly
A12: str-10 | B12: family | C12: uncle (fui's husband) | D12: fuaa | E12: handout | G12: tts | I12: Rhyme Unit 3
A13: str-11 | B13: family | C13: aunt (mother's sister) | D13: maasi | E13: handout | G13: tts | I13: Rhyme Unit 3. Confirmed by Freelang exactly
A14: str-12 | B14: family | C14: uncle (maasi's husband) | D14: maasa | E14: handout | G14: tts | I14: Rhyme Unit 3
... A29: str-27 | B29: jobs | C29: tailor | D29: darji | E29: handout | G29: tts | I29: WhatsApp chat, 17/03/2025 — answered directly by Meena Aunty

Sheet Scene — Charades
A1: id | B1: group | C1: english | D1: kutchi_draft | E1: draft_source | F1: kutchi_confirmed | G1: audio_status | H1: image_ref | I1: notes
A2: cha-01 | B2: action | C2: walking | D2: halato / halati | E2: handout | G2: tts | I2: Unit 4
A3: cha-02 | B3: action | C3: running | D3: dhodato / dhodati | E3: handout | G3: tts | I3: Unit 4
A4: cha-03 | B4: action | C4: jumping | D4: kudka mariato / mariyati | E4: handout | G4: tts | I4: Unit 4
A5: cha-04 | B5: action | C5: reading (a book) | D5: chopdi vanchiyato / vanchiyati | E5: handout | G5: tts | I5: Unit 4. chopdi = book
A6: cha-05 | B6: action | C6: studying | D6: bhanato / bhanati | E6: handout | G6: tts | I6: Unit 4
A7: cha-06 | B7: action | C7: cooking | D7: khadhejo bhanaiyato / bhanaiati | E7: handout | G7: tts | I7: Unit 4
A8: cha-07 | B8: action | C8: playing | D8: ramato / ramati | E8: handout | G8: tts | I8: Unit 4. Freelang confirms the root 'ram-' (play = ramanjo, playing = rameto/rameti)
A9: cha-08 | B9: action | C9: eating | D9: jamato / jamati | E9: handout | G9: tts | I9: Unit 4. Also 'khaiato/khaiati' in Rhyme Unit 6 — two verbs seen, needs the family. Freelang confirms the root 'khai-' (eating = khai to/khai ti)
A10: cha-09 | B10: action | C10: bathing | D10: naiyato / naiyati | E10: handout | G10: tts | I10: Unit 4. Freelang confirms the root 'ang(o)r-' (bath = angor, bathing = angoreto)
A11: cha-10 | B11: action | C11: resting | D11: aaram kaiyato / kaiyati | E11: handout | G11: tts | I11: Unit 4
A12: cha-11 | B12: action | C12: going out | D12: baar vanato / vanati | E12: handout | G12: tts | I12: Unit 4. Freelang confirms 'baare' = outside
A13: cha-12 | B13: action | C13: roaming around | D13: farato / farati | E13: handout | G13: tts | I13: Unit 4
... A16: cha-15 | B16: action | C16: waiting | D16: vaaT nerni | E16: handout | G16: tts | I16: Unit 9 - Vocabulary Builder.pdf

Sheet Scene — Clinic
A1: id | B1: group | C1: english | D1: kutchi_draft | E1: draft_source | F1: kutchi_confirmed | G1: audio_status | H1: image_ref | I1: notes
A2: cli-01 | B2: body part | C2: head | D2: matho | E2: handout | G2: tts | I2: Unit 5 - mo.pdf; Unit 5 - Sharir ja bhag.pdf. Confirmed by Freelang ('mattho')
A3: cli-02 | B3: body part | C3: hair | D3: vaar | E3: handout | G3: tts | I3: CONFLICT — Unit 5 - mo.pdf. Freelang gives an entirely different word, 'mwaara'. Needs the family
A4: cli-03 | B4: body part | C4: forehead | D4: kapaaL | E4: handout | G4: tts | I4: CONFLICT — Unit 5 - mo.pdf. Freelang gives an entirely different word, 'pesaani'. Needs the family
A5: cli-04 | B5: body part | C5: eye | D5: akh | E5: handout | G5: tts | I5: Unit 5 - mo.pdf. Confirmed by Freelang exactly
A6: cli-05 | B6: body part | C6: nose | D6: nak | E6: handout | G6: tts | I6: Unit 5 - mo.pdf. Confirmed by Freelang exactly
A7: cli-06 | B7: body part | C7: cheek | D7: gaal | E7: handout | G7: tts | I7: Unit 5 - mo.pdf. Not in Freelang
A8: cli-07 | B8: body part | C8: mouth | D8: mo | E8: handout | G8: tts | I8: Unit 5 - mo.pdf. Freelang gives 'muh' — likely the same word, spelling variant
A9: cli-08 | B9: body part | C9: teeth | D9: dandh | E9: handout | G9: tts | I9: Unit 5 - mo.pdf. Confirmed by Freelang exactly — and Freelang separately gives the singular, 'tooth = dand', a useful singular/plural pair
A10: cli-09 | B10: body part | C10: tongue | D10: jabh | E10: handout | G10: tts | I10: CONFLICT — Unit 5 - mo.pdf. Freelang gives a different word, 'jib' (closer to standard Gujarati/Hindi 'jeebh') — could be the same word transcribed differently, or a real difference. Needs the family
A11: cli-10 | B11: body part | C11: ear | D11: kan | E11: handout | G11: tts | I11: Unit 5 - mo.pdf. Confirmed by Freelang exactly
A12: cli-11 | B12: body part | C12: neck | D12: galo | E12: handout | G12: tts | I12: CONFLICT — Unit 5 - Sharir ja bhag.pdf. Freelang gives a different word, 'dok', for neck. Possibly 'galo' means throat specifically. Needs the family
A13: cli-12 | B13: body part | C13: brain | D13: magaj | E13: handout | G13: tts | I13: CONFLICT — Unit 5 - Sharir ja bhag.pdf. Freelang gives 'bhejo' for brain, and separately gives 'magaj' for MIND — so the handout's 'magaj' may actually mean mind rather than the physical brain. Needs the family
... A31: cli-30 | B31: illness | C31: medicine / tablet | D31: dhava / gori | E31: handout | G31: tts | I31: Unit 5. Freelang confirms 'medicine = davaa' — spelling variant

Sheet Scene — Hide and Seek
A1: id | B1: group | C1: english | D1: kutchi_draft | E1: draft_source | F1: kutchi_confirmed | G1: audio_status | H1: image_ref | I1: notes
A2: hns-01 | B2: preposition | C2: I live in the village | D2: Aau gaam mai raati/raato | E2: handout | G2: tts | I2: Unit 7
A3: hns-02 | B3: preposition | C3: on the hill | D3: paad te | E3: handout | G3: tts | I3: Unit 7
A4: hns-03 | B4: preposition | C4: next to the temple | D4: mandir ji baju mai | E4: handout | G4: tts | I4: Unit 7
A5: hns-04 | B5: preposition | C5: opposite the mosque | D5: masjid ji saame | E5: handout | G5: tts | I5: Unit 7
A6: hns-05 | B6: preposition | C6: behind the toy shop | D6: ramakde ji dhokaan ji pothiya | E6: handout | G6: tts | I6: Unit 7
A7: hns-06 | B7: preposition | C7: near the beach | D7: dharie je najik | E7: handout | G7: tts | I7: Unit 7
A8: hns-07 | B8: preposition | C8: in a narrow lane | D8: nandhi gali mai | E8: handout | G8: tts | I8: Unit 7
A9: hns-08 | B9: preposition | C9: in front of the market | D9: bajaar ji agiya | E9: handout | G9: tts | I9: Unit 7
A10: hns-09 | B10: preposition | C10: in the middle of the village | D10: gaam je vacha me | E10: handout | G10: tts | I10: Unit 7

Sheet Scene — Pack the Bag
A1: id | B1: group | C1: english | D1: kutchi_draft | E1: draft_source | F1: kutchi_confirmed | G1: audio_status | H1: image_ref | I1: notes
A2: ptb-01 | B2: getting ready | C2: ready | D2: taiyar | E2: handout | G2: tts | I2: Unit 9 - Vocabulary Builder.pdf; Unit 9
A3: ptb-02 | B3: getting ready | C3: door | D3: dharvaja | E3: handout | G3: tts | I3: Unit 9 - Vocabulary Builder.pdf. Freelang confirms ('darwaajo')
A4: ptb-03 | B4: getting ready | C4: window | D4: bari | E4: handout | G4: tts | I4: Unit 9 - Vocabulary Builder.pdf. Freelang confirms ('baari')
A5: ptb-04 | B5: getting ready | C5: minute | D5: miniT | E5: handout | G5: tts | I5: Unit 9 - Vocabulary Builder.pdf; Unit 9. Loanword, confirmed by Freelang's general vocabulary style
A6: ptb-05 | B6: getting ready | C6: socks | D6: moja | E6: handout | G6: tts | I6: Unit 9 - Vocabulary Builder.pdf; Unit 9
A7: ptb-06 | B7: getting ready | C7: shoes | D7: boot | E7: handout | G7: tts | I7: Unit 9 - Vocabulary Builder.pdf; Unit 9. Freelang gives a different word, 'jhoraa', for shoes — needs the family
A8: ptb-07 | B8: getting ready | C8: kitchen | D8: rasodo | E8: handout | G8: tts | I8: Unit 9 - Vocabulary Builder.pdf; Unit 9
A9: ptb-08 | B9: getting ready | C9: a little | D9: thoDi | E9: handout | G9: tts | I9: Unit 9 - Vocabulary Builder.pdf; Unit 9
A10: ptb-09 | B10: getting ready | C10: plate | D10: thaLi | E10: handout | G10: tts | I10: Unit 9 - Vocabulary Builder.pdf; Unit 9
A11: ptb-10 | B11: getting ready | C11: papad (food) | D11: papaD | E11: handout | G11: tts | I11: Unit 9 - Vocabulary Builder.pdf; Unit 9
A12: ptb-11 | B12: getting ready | C12: to wear | D12: pernu | E12: handout | G12: tts | I12: Unit 9 - Vocabulary Builder.pdf
A13: ptb-12 | B13: getting ready | C13: to wait | D13: vaaT nerni | E13: handout | G13: tts | I13: Unit 9 - Vocabulary Builder.pdf
A14: ptb-13 | B14: getting ready | C14: ok / yes / alright | D14: Bhale | E14: handout | G14: tts | I14: Unit 8; Unit 9

Sheet Scene — Bonus
A1: id | B1: group | C1: english | D1: kutchi_draft | E1: draft_source | F1: kutchi_confirmed | G1: audio_status | H1: image_ref | I1: notes
A2: bon-01 | B2: days of week | C2: Monday | D2: Somvaar | E2: handout | G2: tts | I2: athvadiaye ja 7 di.pdf
A3: bon-02 | B3: days of week | C3: Tuesday | D3: Mangalvaar | E3: handout | G3: tts | I3: athvadiaye ja 7 di.pdf
A4: bon-03 | B4: days of week | C4: Wednesday | D4: Budhvaar | E4: handout | G4: tts | I4: athvadiaye ja 7 di.pdf
A5: bon-04 | B5: days of week | C5: Thursday | D5: Ghuruvaar | E5: handout | G5: tts | I5: athvadiaye ja 7 di.pdf
A6: bon-05 | B6: days of week | C6: Friday | D6: Shukravaar | E6: handout | G6: tts | I6: athvadiaye ja 7 di.pdf
A7: bon-06 | B7: days of week | C7: Saturday | D7: Shanivaar | E7: handout | G7: tts | I7: athvadiaye ja 7 di.pdf
A8: bon-07 | B8: days of week | C8: Sunday | D8: Ravivaar | E8: handout | G8: tts | I8: athvadiaye ja 7 di.pdf
A9: bon-08 | B9: numbers (bonus) | C9: twenty | D9: vee | E9: handout | G9: tts | I9: Unit 1 - Rhyme.pdf. Confirmed by Freelang ('vi')
A10: bon-09 | B10: numbers (bonus) | C10: thirty | D10: ttri | E10: freelang | G10: tts | I10: Not in the handouts. From Freelang
A11: bon-10 | B11: numbers (bonus) | C11: forty | D11: chaari | E11: freelang | G11: tts | I11: Not in the handouts. From Freelang
A12: bon-11 | B12: extra (chat) | C12: choose | D12: pasandh | E12: handout | G12: tts | I12: WhatsApp chat, 17/03/2025 — answered directly by Meena Aunty
A13: bon-12 | B13: extra (chat) | C13: lesson | D13: lesson | E13: loanword | G13: tts | I13: WhatsApp chat, 17/03/2025
... A20: bon-19 | B20: extra (chat) | C20: message | D20: vaavad | E20: handout | G20: tts | I20: WhatsApp chat, 17/03/2025
A21: bon-20 | B21: unresolved | C21: unidentified fruit word | D21: chabhaD | G21: tts | I21: FaL.pdf — listed among fruit, meaning unclear, needs the family. Not in Freelang
A22: bon-21 | B22: unresolved | C22: unidentified fruit word (maybe jackfruit) | D22: Papnas | G22: tts | I22: FaL.pdf — listed among fruit, meaning unclear, needs the family. Not in Freelang
A23: bon-22 | B23: unresolved | C23: 'Aalu' in the fruit list | D23: Aalu | G23: tts | I23: FaL.pdf; Rhyme Unit 6 ('chaar aalu') — Aalu usually means potato, but it's grouped with fruit here. A guess worth putting to the family directly: Urdu/Hindi 'aloo bukhara' means dried plum, and 'aloo' alone sometimes stands for plum in that phrase — 'aalu' here may mean plum, not potato. This is Claude's inference, not a sourced answer, needs the family

Sheet Dictionary — Freelang raw
A1: The full Freelang Kutchi-English dictionary (Burhan Khamisa's compilation), pasted by Zafar via the Freelang website's search sidebar, 496 unique entries. One person's record, same evidentiary weight as the blog dictionary — real attested Kutchi, but not the family's Kutchi, and not cross-checked against them. Kept here in full for reference when later scenes need a word not yet covered elsewhere in this file.
A2: english | B2: kutchi
A3: african female | B3: goli
A4: african male | B4: golo
A5: africans | B5: golaa
A6: after, then | B6: pacchi
A7: afternoon | B7: sanjo
A8: air | B8: havaa
A9: alarm | B9: gantri
A10: alcohol | B10: daaru
A11: alone | B11: ekhli
A12: anger | B12: gusso
A13: animal | B13: jaanwar
... A498: your | B498: toke

Sheet All words — master
A1: Read-only. Every row here is a formula pointing at a scene tab — this sheet is built FROM the scene tabs, never the other way round. To fix a word, go to its scene tab and edit kutchi_confirmed there; this list updates itself. (The Bazaar tab's plural columns are not mirrored here — open that tab directly for those.)
A2: id | B2: scene | C2: group | D2: english | E2: kutchi_draft | F2: draft_source | G2: kutchi_confirmed | H2: audio_status
A3: =IF('Scene — Bazaar'!A2="","",'Scene — Bazaar'!A2) -> fru-01 | B3: Bazaar | C3: =IF('Scene — Bazaar'!B2="","",'Scene — Bazaar'!B2) -> fruit | D3: =IF('Scene — Bazaar'!C2="","",'Scene — Bazaar'!C2) -> banana | E3: =IF('Scene — Bazaar'!D2="","",'Scene — Bazaar'!D2) -> kelo | F3: =IF('Scene — Bazaar'!E2="","",'Scene — Bazaar'!E2) -> handout | G3: =IF('Scene — Bazaar'!F2="","",'Scene — Bazaar'!F2) | H3: =IF('Scene — Bazaar'!G2="","",'Scene — Bazaar'!G2) -> tts
A4: =IF('Scene — Bazaar'!A3="","",'Scene — Bazaar'!A3) -> fru-02 | B4: Bazaar | C4: =IF('Scene — Bazaar'!B3="","",'Scene — Bazaar'!B3) -> fruit | D4: =IF('Scene — Bazaar'!C3="","",'Scene — Bazaar'!C3) -> lemon | E4: =IF('Scene — Bazaar'!D3="","",'Scene — Bazaar'!D3) -> limu | F4: =IF('Scene — Bazaar'!E3="","",'Scene — Bazaar'!E3) -> handout | G4: =IF('Scene — Bazaar'!F3="","",'Scene — Bazaar'!F3) | H4: =IF('Scene — Bazaar'!G3="","",'Scene — Bazaar'!G3) -> tts
A5: =IF('Scene — Bazaar'!A4="","",'Scene — Bazaar'!A4) -> fru-03 | B5: Bazaar | C5: =IF('Scene — Bazaar'!B4="","",'Scene — Bazaar'!B4) -> fruit | D5: =IF('Scene — Bazaar'!C4="","",'Scene — Bazaar'!C4) -> papaya | E5: =IF('Scene — Bazaar'!D4="","",'Scene — Bazaar'!D4) -> papaiyo | F5: =IF('Scene — Bazaar'!E4="","",'Scene — Bazaar'!E4) -> handout | G5: =IF('Scene — Bazaar'!F4="","",'Scene — Bazaar'!F4) | H5: =IF('Scene — Bazaar'!G4="","",'Scene — Bazaar'!G4) -> tts
A6: =IF('Scene — Bazaar'!A5="","",'Scene — Bazaar'!A5) -> fru-04 | B6: Bazaar | C6: =IF('Scene — Bazaar'!B5="","",'Scene — Bazaar'!B5) -> fruit | D6: =IF('Scene — Bazaar'!C5="","",'Scene — Bazaar'!C5) -> orange | E6: =IF('Scene — Bazaar'!D5="","",'Scene — Bazaar'!D5) -> santra | F6: =IF('Scene — Bazaar'!E5="","",'Scene — Bazaar'!E5) -> handout | G6: =IF('Scene — Bazaar'!F5="","",'Scene — Bazaar'!F5) | H6: =IF('Scene — Bazaar'!G5="","",'Scene — Bazaar'!G5) -> tts
A7: =IF('Scene — Bazaar'!A6="","",'Scene — Bazaar'!A6) -> fru-05 | B7: Bazaar | C7: =IF('Scene — Bazaar'!B6="","",'Scene — Bazaar'!B6) -> fruit | D7: =IF('Scene — Bazaar'!C6="","",'Scene — Bazaar'!C6) -> mango | E7: =IF('Scene — Bazaar'!D6="","",'Scene — Bazaar'!D6) -> aamo | F7: =IF('Scene — Bazaar'!E6="","",'Scene — Bazaar'!E6) -> handout | G7: =IF('Scene — Bazaar'!F6="","",'Scene — Bazaar'!F6) | H7: =IF('Scene — Bazaar'!G6="","",'Scene — Bazaar'!G6) -> tts
A8: =IF('Scene — Bazaar'!A7="","",'Scene — Bazaar'!A7) -> fru-06 | B8: Bazaar | C8: =IF('Scene — Bazaar'!B7="","",'Scene — Bazaar'!B7) -> fruit | D8: =IF('Scene — Bazaar'!C7="","",'Scene — Bazaar'!C7) -> pear | E8: =IF('Scene — Bazaar'!D7="","",'Scene — Bazaar'!D7) -> naaspati | F8: =IF('Scene — Bazaar'!E7="","",'Scene — Bazaar'!E7) -> handout | G8: =IF('Scene — Bazaar'!F7="","",'Scene — Bazaar'!F7) | H8: =IF('Scene — Bazaar'!G7="","",'Scene — Bazaar'!G7) -> tts
A9: =IF('Scene — Bazaar'!A8="","",'Scene — Bazaar'!A8) -> fru-07 | B9: Bazaar | C9: =IF('Scene — Bazaar'!B8="","",'Scene — Bazaar'!B8) -> fruit | D9: =IF('Scene — Bazaar'!C8="","",'Scene — Bazaar'!C8) -> kiwi | E9: =IF('Scene — Bazaar'!D8="","",'Scene — Bazaar'!D8) -> kivi | F9: =IF('Scene — Bazaar'!E8="","",'Scene — Bazaar'!E8) -> handout | G9: =IF('Scene — Bazaar'!F8="","",'Scene — Bazaar'!F8) | H9: =IF('Scene — Bazaar'!G8="","",'Scene — Bazaar'!G8) -> tts
A10: =IF('Scene — Bazaar'!A9="","",'Scene — Bazaar'!A9) -> fru-08 | B10: Bazaar | C10: =IF('Scene — Bazaar'!B9="","",'Scene — Bazaar'!B9) -> fruit | D10: =IF('Scene — Bazaar'!C9="","",'Scene — Bazaar'!C9) -> apple | E10: =IF('Scene — Bazaar'!D9="","",'Scene — Bazaar'!D9) -> safarjan | F10: =IF('Scene — Bazaar'!E9="","",'Scene — Bazaar'!E9) -> handout | G10: =IF('Scene — Bazaar'!F9="","",'Scene — Bazaar'!F9) | H10: =IF('Scene — Bazaar'!G9="","",'Scene — Bazaar'!G9) -> tts
A11: =IF('Scene — Bazaar'!A10="","",'Scene — Bazaar'!A10) -> fru-09 | B11: Bazaar | C11: =IF('Scene — Bazaar'!B10="","",'Scene — Bazaar'!B10) -> fruit | D11: =IF('Scene — Bazaar'!C10="","",'Scene — Bazaar'!C10) -> coconut | E11: =IF('Scene — Bazaar'!D10="","",'Scene — Bazaar'!D10) -> naariyel | F11: =IF('Scene — Bazaar'!E10="","",'Scene — Bazaar'!E10) -> handout | G11: =IF('Scene — Bazaar'!F10="","",'Scene — Bazaar'!F10) | H11: =IF('Scene — Bazaar'!G10="","",'Scene — Bazaar'!G10) -> tts
A12: =IF('Scene — Bazaar'!A11="","",'Scene — Bazaar'!A11) -> fru-10 | B12: Bazaar | C12: =IF('Scene — Bazaar'!B11="","",'Scene — Bazaar'!B11) -> fruit | D12: =IF('Scene — Bazaar'!C11="","",'Scene — Bazaar'!C11) -> fig | E12: =IF('Scene — Bazaar'!D11="","",'Scene — Bazaar'!D11) -> anjir | F12: =IF('Scene — Bazaar'!E11="","",'Scene — Bazaar'!E11) -> handout | G12: =IF('Scene — Bazaar'!F11="","",'Scene — Bazaar'!F11) | H12: =IF('Scene — Bazaar'!G11="","",'Scene — Bazaar'!G11) -> tts
A13: =IF('Scene — Bazaar'!A12="","",'Scene — Bazaar'!A12) -> fru-11 | B13: Bazaar | C13: =IF('Scene — Bazaar'!B12="","",'Scene — Bazaar'!B12) -> fruit | D13: =IF('Scene — Bazaar'!C12="","",'Scene — Bazaar'!C12) -> grapes | E13: =IF('Scene — Bazaar'!D12="","",'Scene — Bazaar'!D12) -> drakhu | F13: =IF('Scene — Bazaar'!E12="","",'Scene — Bazaar'!E12) -> handout | G13: =IF('Scene — Bazaar'!F12="","",'Scene — Bazaar'!F12) | H13: =IF('Scene — Bazaar'!G12="","",'Scene — Bazaar'!G12) -> tts
A14: =IF('Scene — Bazaar'!A13="","",'Scene — Bazaar'!A13) -> fru-12 | B14: Bazaar | C14: =IF('Scene — Bazaar'!B13="","",'Scene — Bazaar'!B13) -> fruit | D14: =IF('Scene — Bazaar'!C13="","",'Scene — Bazaar'!C13) -> pineapple | E14: =IF('Scene — Bazaar'!D13="","",'Scene — Bazaar'!D13) -> ananas | F14: =IF('Scene — Bazaar'!E13="","",'Scene — Bazaar'!E13) -> handout | G14: =IF('Scene — Bazaar'!F13="","",'Scene — Bazaar'!F13) | H14: =IF('Scene — Bazaar'!G13="","",'Scene — Bazaar'!G13) -> tts
... A60: =IF('Scene — Bazaar'!A59="","",'Scene — Bazaar'!A59) -> num-10 | B60: Bazaar | C60: =IF('Scene — Bazaar'!B59="","",'Scene — Bazaar'!B59) -> number | D60: =IF('Scene — Bazaar'!C59="","",'Scene — Bazaar'!C59) -> ten | E60: =IF('Scene — Bazaar'!D59="","",'Scene — Bazaar'!D59) -> do | F60: =IF('Scene — Bazaar'!E59="","",'Scene — Bazaar'!E59) -> handout | G60: =IF('Scene — Bazaar'!F59="","",'Scene — Bazaar'!F59) | H60: =IF('Scene — Bazaar'!G59="","",'Scene — Bazaar'!G59) -> tts
A61: =IF('Scene — Doorstep'!A2="","",'Scene — Doorstep'!A2) -> door-01 | B61: Doorstep | C61: =IF('Scene — Doorstep'!B2="","",'Scene — Doorstep'!B2) -> greeting | D61: =IF('Scene — Doorstep'!C2="","",'Scene — Doorstep'!C2) -> how are you | E61: =IF('Scene — Doorstep'!D2="","",'Scene — Doorstep'!D2) -> Ki aiye? / Ki ayo? | F61: =IF('Scene — Doorstep'!E2="","",'Scene — Doorstep'!E2) -> handout | G61: =IF('Scene — Doorstep'!F2="","",'Scene — Doorstep'!F2) | H61: =IF('Scene — Doorstep'!G2="","",'Scene — Doorstep'!G2) -> tts
A62: =IF('Scene — Doorstep'!A3="","",'Scene — Doorstep'!A3) -> door-02 | B62: Doorstep | C62: =IF('Scene — Doorstep'!B3="","",'Scene — Doorstep'!B3) -> greeting | D62: =IF('Scene — Doorstep'!C3="","",'Scene — Doorstep'!C3) -> I am fine | E62: =IF('Scene — Doorstep'!D3="","",'Scene — Doorstep'!D3) -> Aau sari/saro aiya | F62: =IF('Scene — Doorstep'!E3="","",'Scene — Doorstep'!E3) -> handout | G62: =IF('Scene — Doorstep'!F3="","",'Scene — Doorstep'!F3) | H62: =IF('Scene — Doorstep'!G3="","",'Scene — Doorstep'!G3) -> tts
A63: =IF('Scene — Doorstep'!A4="","",'Scene — Doorstep'!A4) -> door-03 | B63: Doorstep | C63: =IF('Scene — Doorstep'!B4="","",'Scene — Doorstep'!B4) -> greeting | D63: =IF('Scene — Doorstep'!C4="","",'Scene — Doorstep'!C4) -> I am fine (alt.) | E63: =IF('Scene — Doorstep'!D4="","",'Scene — Doorstep'!D4) -> Aau majame | F63: =IF('Scene — Doorstep'!E4="","",'Scene — Doorstep'!E4) -> handout | G63: =IF('Scene — Doorstep'!F4="","",'Scene — Doorstep'!F4) | H63: =IF('Scene — Doorstep'!G4="","",'Scene — Doorstep'!G4) -> tts
A64: =IF('Scene — Doorstep'!A5="","",'Scene — Doorstep'!A5) -> door-04 | B64: Doorstep | C64: =IF('Scene — Doorstep'!B5="","",'Scene — Doorstep'!B5) -> greeting | D64: =IF('Scene — Doorstep'!C5="","",'Scene — Doorstep'!C5) -> I am fine (alt.) | E64: =IF('Scene — Doorstep'!D5="","",'Scene — Doorstep'!D5) -> Aau bharobhar aiya | F64: =IF('Scene — Doorstep'!E5="","",'Scene — Doorstep'!E5) -> handout | G64: =IF('Scene — Doorstep'!F5="","",'Scene — Doorstep'!F5) | H64: =IF('Scene — Doorstep'!G5="","",'Scene — Doorstep'!G5) -> tts
A65: =IF('Scene — Doorstep'!A6="","",'Scene — Doorstep'!A6) -> door-05 | B65: Doorstep | C65: =IF('Scene — Doorstep'!B6="","",'Scene — Doorstep'!B6) -> greeting | D65: =IF('Scene — Doorstep'!C6="","",'Scene — Doorstep'!C6) -> I am fine (alt.) | E65: =IF('Scene — Doorstep'!D6="","",'Scene — Doorstep'!D6) -> Aau thik aiya | F65: =IF('Scene — Doorstep'!E6="","",'Scene — Doorstep'!E6) -> handout | G65: =IF('Scene — Doorstep'!F6="","",'Scene — Doorstep'!F6) | H65: =IF('Scene — Doorstep'!G6="","",'Scene — Doorstep'!G6) -> tts
A66: =IF('Scene — Doorstep'!A7="","",'Scene — Doorstep'!A7) -> door-06 | B66: Doorstep | C66: =IF('Scene — Doorstep'!B7="","",'Scene — Doorstep'!B7) -> greeting | D66: =IF('Scene — Doorstep'!C7="","",'Scene — Doorstep'!C7) -> I am ill | E66: =IF('Scene — Doorstep'!D7="","",'Scene — Doorstep'!D7) -> Aau mando/mandi aiya | F66: =IF('Scene — Doorstep'!E7="","",'Scene — Doorstep'!E7) -> handout | G66: =IF('Scene — Doorstep'!F7="","",'Scene — Doorstep'!F7) | H66: =IF('Scene — Doorstep'!G7="","",'Scene — Doorstep'!G7) -> tts
A67: =IF('Scene — Doorstep'!A8="","",'Scene — Doorstep'!A8) -> door-07 | B67: Doorstep | C67: =IF('Scene — Doorstep'!B8="","",'Scene — Doorstep'!B8) -> greeting | D67: =IF('Scene — Doorstep'!C8="","",'Scene — Doorstep'!C8) -> I am tired | E67: =IF('Scene — Doorstep'!D8="","",'Scene — Doorstep'!D8) -> Aau thake rai/ryo aiya | F67: =IF('Scene — Doorstep'!E8="","",'Scene — Doorstep'!E8) -> handout | G67: =IF('Scene — Doorstep'!F8="","",'Scene — Doorstep'!F8) | H67: =IF('Scene — Doorstep'!G8="","",'Scene — Doorstep'!G8) -> tts
A68: =IF('Scene — Doorstep'!A9="","",'Scene — Doorstep'!A9) -> door-08 | B68: Doorstep | C68: =IF('Scene — Doorstep'!B9="","",'Scene — Doorstep'!B9) -> greeting | D68: =IF('Scene — Doorstep'!C9="","",'Scene — Doorstep'!C9) -> I am not well | E68: =IF('Scene — Doorstep'!D9="","",'Scene — Doorstep'!D9) -> Muke thik naay | F68: =IF('Scene — Doorstep'!E9="","",'Scene — Doorstep'!E9) -> handout | G68: =IF('Scene — Doorstep'!F9="","",'Scene — Doorstep'!F9) | H68: =IF('Scene — Doorstep'!G9="","",'Scene — Doorstep'!G9) -> tts
A69: =IF('Scene — Doorstep'!A10="","",'Scene — Doorstep'!A10) -> door-09 | B69: Doorstep | C69: =IF('Scene — Doorstep'!B10="","",'Scene — Doorstep'!B10) -> greeting | D69: =IF('Scene — Doorstep'!C10="","",'Scene — Doorstep'!C10) -> peace be upon you | E69: =IF('Scene — Doorstep'!D10="","",'Scene — Doorstep'!D10) -> Salamun alaykum | F69: =IF('Scene — Doorstep'!E10="","",'Scene — Doorstep'!E10) -> handout | G69: =IF('Scene — Doorstep'!F10="","",'Scene — Doorstep'!F10) | H69: =IF('Scene — Doorstep'!G10="","",'Scene — Doorstep'!G10) -> tts
A70: =IF('Scene — Doorstep'!A11="","",'Scene — Doorstep'!A11) -> door-10 | B70: Doorstep | C70: =IF('Scene — Doorstep'!B11="","",'Scene — Doorstep'!B11) -> greeting | D70: =IF('Scene — Doorstep'!C11="","",'Scene — Doorstep'!C11) -> and peace be upon you | E70: =IF('Scene — Doorstep'!D11="","",'Scene — Doorstep'!D11) -> Wa alaikum salaam | F70: =IF('Scene — Doorstep'!E11="","",'Scene — Doorstep'!E11) -> handout | G70: =IF('Scene — Doorstep'!F11="","",'Scene — Doorstep'!F11) | H70: =IF('Scene — Doorstep'!G11="","",'Scene — Doorstep'!G11) -> tts
A71: =IF('Scene — Street'!A3="","",'Scene — Street'!A3) -> str-01 | B71: Street | C71: =IF('Scene — Street'!B3="","",'Scene — Street'!B3) -> family | D71: =IF('Scene — Street'!C3="","",'Scene — Street'!C3) -> father | E71: =IF('Scene — Street'!D3="","",'Scene — Street'!D3) -> adhha / bapuji | F71: =IF('Scene — Street'!E3="","",'Scene — Street'!E3) -> handout | G71: =IF('Scene — Street'!F3="","",'Scene — Street'!F3) | H71: =IF('Scene — Street'!G3="","",'Scene — Street'!G3) -> tts
A72: =IF('Scene — Street'!A4="","",'Scene — Street'!A4) -> str-02 | B72: Street | C72: =IF('Scene — Street'!B4="","",'Scene — Street'!B4) -> family | D72: =IF('Scene — Street'!C4="","",'Scene — Street'!C4) -> mother | E72: =IF('Scene — Street'!D4="","",'Scene — Street'!D4) -> baai | F72: =IF('Scene — Street'!E4="","",'Scene — Street'!E4) -> handout | G72: =IF('Scene — Street'!F4="","",'Scene — Street'!F4) | H72: =IF('Scene — Street'!G4="","",'Scene — Street'!G4) -> tts
A73: =IF('Scene — Street'!A5="","",'Scene — Street'!A5) -> str-03 | B73: Street | C73: =IF('Scene — Street'!B5="","",'Scene — Street'!B5) -> family | D73: =IF('Scene — Street'!C5="","",'Scene — Street'!C5) -> grandfather (paternal) | E73: =IF('Scene — Street'!D5="","",'Scene — Street'!D5) -> dadobapa | F73: =IF('Scene — Street'!E5="","",'Scene — Street'!E5) -> handout | G73: =IF('Scene — Street'!F5="","",'Scene — Street'!F5) | H73: =IF('Scene — Street'!G5="","",'Scene — Street'!G5) -> tts
A74: =IF('Scene — Street'!A6="","",'Scene — Street'!A6) -> str-04 | B74: Street | C74: =IF('Scene — Street'!B6="","",'Scene — Street'!B6) -> family | D74: =IF('Scene — Street'!C6="","",'Scene — Street'!C6) -> grandmother (paternal) | E74: =IF('Scene — Street'!D6="","",'Scene — Street'!D6) -> dadi | F74: =IF('Scene — Street'!E6="","",'Scene — Street'!E6) -> handout | G74: =IF('Scene — Street'!F6="","",'Scene — Street'!F6) | H74: =IF('Scene — Street'!G6="","",'Scene — Street'!G6) -> tts
A75: =IF('Scene — Street'!A7="","",'Scene — Street'!A7) -> str-05 | B75: Street | C75: =IF('Scene — Street'!B7="","",'Scene — Street'!B7) -> family | D75: =IF('Scene — Street'!C7="","",'Scene — Street'!C7) -> grandmother (maternal) | E75: =IF('Scene — Street'!D7="","",'Scene — Street'!D7) -> naani | F75: =IF('Scene — Street'!E7="","",'Scene — Street'!E7) -> handout | G75: =IF('Scene — Street'!F7="","",'Scene — Street'!F7) | H75: =IF('Scene — Street'!G7="","",'Scene — Street'!G7) -> tts
A76: =IF('Scene — Street'!A8="","",'Scene — Street'!A8) -> str-06 | B76: Street | C76: =IF('Scene — Street'!B8="","",'Scene — Street'!B8) -> family | D76: =IF('Scene — Street'!C8="","",'Scene — Street'!C8) -> grandfather (maternal) | E76: =IF('Scene — Street'!D8="","",'Scene — Street'!D8) -> naanobapa | F76: =IF('Scene — Street'!E8="","",'Scene — Street'!E8) -> handout | G76: =IF('Scene — Street'!F8="","",'Scene — Street'!F8) | H76: =IF('Scene — Street'!G8="","",'Scene — Street'!G8) -> tts
A77: =IF('Scene — Street'!A9="","",'Scene — Street'!A9) -> str-07 | B77: Street | C77: =IF('Scene — Street'!B9="","",'Scene — Street'!B9) -> family | D77: =IF('Scene — Street'!C9="","",'Scene — Street'!C9) -> brother | E77: =IF('Scene — Street'!D9="","",'Scene — Street'!D9) -> bha | F77: =IF('Scene — Street'!E9="","",'Scene — Street'!E9) -> handout | G77: =IF('Scene — Street'!F9="","",'Scene — Street'!F9) | H77: =IF('Scene — Street'!G9="","",'Scene — Street'!G9) -> tts
A78: =IF('Scene — Street'!A10="","",'Scene — Street'!A10) -> str-08 | B78: Street | C78: =IF('Scene — Street'!B10="","",'Scene — Street'!B10) -> family | D78: =IF('Scene — Street'!C10="","",'Scene — Street'!C10) -> sister | E78: =IF('Scene — Street'!D10="","",'Scene — Street'!D10) -> bheN | F78: =IF('Scene — Street'!E10="","",'Scene — Street'!E10) -> handout | G78: =IF('Scene — Street'!F10="","",'Scene — Street'!F10) | H78: =IF('Scene — Street'!G10="","",'Scene — Street'!G10) -> tts
A79: =IF('Scene — Street'!A11="","",'Scene — Street'!A11) -> str-09 | B79: Street | C79: =IF('Scene — Street'!B11="","",'Scene — Street'!B11) -> family | D79: =IF('Scene — Street'!C11="","",'Scene — Street'!C11) -> aunt (father's sister) | E79: =IF('Scene — Street'!D11="","",'Scene — Street'!D11) -> fui | F79: =IF('Scene — Street'!E11="","",'Scene — Street'!E11) -> handout | G79: =IF('Scene — Street'!F11="","",'Scene — Street'!F11) | H79: =IF('Scene — Street'!G11="","",'Scene — Street'!G11) -> tts
A80: =IF('Scene — Street'!A12="","",'Scene — Street'!A12) -> str-10 | B80: Street | C80: =IF('Scene — Street'!B12="","",'Scene — Street'!B12) -> family | D80: =IF('Scene — Street'!C12="","",'Scene — Street'!C12) -> uncle (fui's husband) | E80: =IF('Scene — Street'!D12="","",'Scene — Street'!D12) -> fuaa | F80: =IF('Scene — Street'!E12="","",'Scene — Street'!E12) -> handout | G80: =IF('Scene — Street'!F12="","",'Scene — Street'!F12) | H80: =IF('Scene — Street'!G12="","",'Scene — Street'!G12) -> tts
A81: =IF('Scene — Street'!A13="","",'Scene — Street'!A13) -> str-11 | B81: Street | C81: =IF('Scene — Street'!B13="","",'Scene — Street'!B13) -> family | D81: =IF('Scene — Street'!C13="","",'Scene — Street'!C13) -> aunt (mother's sister) | E81: =IF('Scene — Street'!D13="","",'Scene — Street'!D13) -> maasi | F81: =IF('Scene — Street'!E13="","",'Scene — Street'!E13) -> handout | G81: =IF('Scene — Street'!F13="","",'Scene — Street'!F13) | H81: =IF('Scene — Street'!G13="","",'Scene — Street'!G13) -> tts
A82: =IF('Scene — Street'!A14="","",'Scene — Street'!A14) -> str-12 | B82: Street | C82: =IF('Scene — Street'!B14="","",'Scene — Street'!B14) -> family | D82: =IF('Scene — Street'!C14="","",'Scene — Street'!C14) -> uncle (maasi's husband) | E82: =IF('Scene — Street'!D14="","",'Scene — Street'!D14) -> maasa | F82: =IF('Scene — Street'!E14="","",'Scene — Street'!E14) -> handout | G82: =IF('Scene — Street'!F14="","",'Scene — Street'!F14) | H82: =IF('Scene — Street'!G14="","",'Scene — Street'!G14) -> tts
... A97: =IF('Scene — Street'!A29="","",'Scene — Street'!A29) -> str-27 | B97: Street | C97: =IF('Scene — Street'!B29="","",'Scene — Street'!B29) -> jobs | D97: =IF('Scene — Street'!C29="","",'Scene — Street'!C29) -> tailor | E97: =IF('Scene — Street'!D29="","",'Scene — Street'!D29) -> darji | F97: =IF('Scene — Street'!E29="","",'Scene — Street'!E29) -> handout | G97: =IF('Scene — Street'!F29="","",'Scene — Street'!F29) | H97: =IF('Scene — Street'!G29="","",'Scene — Street'!G29) -> tts
A98: =IF('Scene — Charades'!A2="","",'Scene — Charades'!A2) -> cha-01 | B98: Charades | C98: =IF('Scene — Charades'!B2="","",'Scene — Charades'!B2) -> action | D98: =IF('Scene — Charades'!C2="","",'Scene — Charades'!C2) -> walking | E98: =IF('Scene — Charades'!D2="","",'Scene — Charades'!D2) -> halato / halati | F98: =IF('Scene — Charades'!E2="","",'Scene — Charades'!E2) -> handout | G98: =IF('Scene — Charades'!F2="","",'Scene — Charades'!F2) | H98: =IF('Scene — Charades'!G2="","",'Scene — Charades'!G2) -> tts
A99: =IF('Scene — Charades'!A3="","",'Scene — Charades'!A3) -> cha-02 | B99: Charades | C99: =IF('Scene — Charades'!B3="","",'Scene — Charades'!B3) -> action | D99: =IF('Scene — Charades'!C3="","",'Scene — Charades'!C3) -> running | E99: =IF('Scene — Charades'!D3="","",'Scene — Charades'!D3) -> dhodato / dhodati | F99: =IF('Scene — Charades'!E3="","",'Scene — Charades'!E3) -> handout | G99: =IF('Scene — Charades'!F3="","",'Scene — Charades'!F3) | H99: =IF('Scene — Charades'!G3="","",'Scene — Charades'!G3) -> tts
...
